[2025-04-10T11:46:53.745+0000] {taskinstance.py:1956} INFO - Dependencies all met for dep_context=non-requeueable deps ti=<TaskInstance: ingest_postgres_to_snowflake.ingest_data manual__2025-04-10T11:46:48+00:00 [queued]>
[2025-04-10T11:46:53.777+0000] {taskinstance.py:1956} INFO - Dependencies all met for dep_context=requeueable deps ti=<TaskInstance: ingest_postgres_to_snowflake.ingest_data manual__2025-04-10T11:46:48+00:00 [queued]>
[2025-04-10T11:46:53.795+0000] {taskinstance.py:2170} INFO - Starting attempt 1 of 2
[2025-04-10T11:46:53.975+0000] {taskinstance.py:2191} INFO - Executing <Task(PythonOperator): ingest_data> on 2025-04-10 11:46:48+00:00
[2025-04-10T11:46:54.196+0000] {standard_task_runner.py:60} INFO - Started process 937 to run task
[2025-04-10T11:46:54.330+0000] {standard_task_runner.py:87} INFO - Running: ['***', 'tasks', 'run', 'ingest_postgres_to_snowflake', 'ingest_data', 'manual__2025-04-10T11:46:48+00:00', '--job-id', '8', '--raw', '--subdir', 'DAGS_FOLDER/ingest_to_snowflake_dag.py', '--cfg-path', '/tmp/tmpm5c59tie']
[2025-04-10T11:46:54.396+0000] {standard_task_runner.py:88} INFO - Job 8: Subtask ingest_data
[2025-04-10T11:46:54.978+0000] {logging_mixin.py:188} WARNING - /home/***/.local/lib/python3.10/site-packages/***/settings.py:194 DeprecationWarning: The sql_alchemy_conn option in [core] has been moved to the sql_alchemy_conn option in [database] - the old setting has been used, but please update your config.
[2025-04-10T11:46:57.168+0000] {task_command.py:423} INFO - Running <TaskInstance: ingest_postgres_to_snowflake.ingest_data manual__2025-04-10T11:46:48+00:00 [running]> on host 65e85360fc1d
[2025-04-10T11:47:01.657+0000] {taskinstance.py:2480} INFO - Exporting env vars: AIRFLOW_CTX_DAG_OWNER='***' AIRFLOW_CTX_DAG_ID='ingest_postgres_to_snowflake' AIRFLOW_CTX_TASK_ID='ingest_data' AIRFLOW_CTX_EXECUTION_DATE='2025-04-10T11:46:48+00:00' AIRFLOW_CTX_TRY_NUMBER='1' AIRFLOW_CTX_DAG_RUN_ID='manual__2025-04-10T11:46:48+00:00'
[2025-04-10T11:47:01.673+0000] {logging_mixin.py:188} INFO - Erreur PostgreSQL: connection to server on socket "/var/run/postgresql/.s.PGSQL.5432" failed: No such file or directory
	Is the server running locally and accepting connections on that socket?
[2025-04-10T11:47:01.677+0000] {python.py:201} INFO - Done. Returned value was: None
[2025-04-10T11:47:01.771+0000] {taskinstance.py:1138} INFO - Marking task as SUCCESS. dag_id=ingest_postgres_to_snowflake, task_id=ingest_data, execution_date=20250410T114648, start_date=20250410T114653, end_date=20250410T114701
[2025-04-10T11:47:01.880+0000] {local_task_job_runner.py:234} INFO - Task exited with return code 0
[2025-04-10T11:47:02.058+0000] {taskinstance.py:3280} INFO - 0 downstream tasks scheduled from follow-on schedule check
